Workbook
Name ArbeidsukeTimer: 'Gruppemedlem 1'!$B$4
Name Kolonnetittel1: #REF!
Name KolonnetittelOmråde1..E6.1: 'Gruppemedlem 1'!$B$3

Sheet Gruppemedlem 1
B1: Timeliste
B2: Navn
B3: Jimmy Bui | C3: Totalt antall arbeidstimer
C4: =SUBTOTAL(109,Timeliste57[Antall arbeidstimer]) -> 116.6
B5: Dato(er) | C5: Antall arbeidstimer | D5: Kommentar | E5: Tagg | H5: Oppgave Tag | I5: Antall oppføringer | J5: Timer arbeid med oppgave | K5: %
B6: 45887 | C6: 2 | E6: Forelesning/WS | H6: Programmering | I6: =COUNTIF(E6:E100, "Programmering") -> 10 | J6: =SUMIF(E6:E100, "Programmering", C6:C100) -> 38 | K6: =J6/C4*100 -> 32.590051
B7: 45888 | C7: 2 | E7: Forelesning/WS | H7: Raport | I7: =COUNTIF(E6:E100, "Raport") -> 8 | J7: =SUMIF(E6:E100, "Raport", C6:C100) -> 16.6 | K7: =J7/C4*100 -> 14.236707
B8: 45891 | C8: 2 | E8: Forelesning/WS | H8: Møte | I8: =COUNTIF(E6:E100, "Møte") -> 2 | J8: =SUMIF(E6:E100, "Møte", C6:C100) -> 4 | K8: =J8/C4*100 -> 3.4305317
B9: 45894 | C9: 2 | E9: Forelesning/WS | H9: Database | I9: =COUNTIF(E6:E100, "Database") -> 0 | J9: =SUMIF(E6:E100, "Database", C6:C100) -> 0 | K9: =J9/C4*100 -> 0
B10: 45895 | C10: 2 | E10: Forelesning/WS | H10: GitHub | I10: =COUNTIF(E6:E100, "GitHub") -> 0 | J10: =SUMIF(E6:E100, "GitHub", C6:C100) -> 0 | K10: =J10/C4*100 -> 0
B11: 45901 | C11: 2 | E11: Forelesning/WS | H11: Administrativt | I11: =COUNTIF(E6:E100, "Administrativt") -> 0 | J11: =SUMIF(E6:E100, "Administrativt", C6:C100) -> 0 | K11: =J11/C4*100 -> 0
B12: 45901 | C12: 1 | E12: Raport | H12: Forelesning/WS | I12: =COUNTIF(E6:E100, "Forelesning/WS") -> 23 | J12: =SUMIF(E6:E100, "Forelesning/WS", C6:C100) -> 46 | K12: =J12/C4*100 -> 39.451115
B13: 45903 | C13: 0.5 | E13: Veiledning | H13: Veiledning | I13: =COUNTIF(E6:E100, "Veiledning") -> 2 | J13: =SUMIF(E6:E100, "Veiledning", C6:C100) -> 1.5 | K13: =J13/C4*100 -> 1.2864494
B14: 45905 | C14: 2 | E14: Forelesning/WS | H14: Design | I14: =COUNTIF(E6:E100, "Design") -> 2 | J14: =SUMIF(E6:E100, "Design", C6:C100) -> 4.5 | K14: =J14/C4*100 -> 3.8593482
B15: 45908 | C15: 2 | E15: Forelesning/WS | H15: Annet | I15: =COUNTIF(E6:E100, "Annet") -> 0 | J15: =SUMIF(E7:E101, "Annet", C6:C100) -> 0 | K15: =J15/C4*100 -> 0
B16: 45912 | C16: 2 | E16: Forelesning/WS
B17: 45912 | C17: 1.3 | E17: Raport
B18: 45915 | C18: 2 | E18: Forelesning/WS
B19: 45919 | C19: 2 | E19: Forelesning/WS
B20: 45922 | C20: 2 | E20: Forelesning/WS
B21: 45929 | C21: 2 | E21: Forelesning/WS
B22: 45930 | C22: 3 | D22: Jobbet med å finne ut hvordan man implementerer login/registrering | E22: Programmering
B23: 45931 | C23: 2 | D23: Jobbet med å finne ut hvordan man implementerer login/registrering | E23: Programmering
B24: 45933 | C24: 3 | D24: Jobbet med sprint. Implementering av autentisering | E24: Programmering
B25: 45935 | C25: 4 | D25: Jobbet med sprint. Ferdig implementert av autentisering | E25: Programmering
B26: 45936 | C26: 2 | E26: Forelesning/WS
B27: 45936 | C27: 2 | E27: Raport
B28: 45937 | C28: 2 | E28: Forelesning/WS
B29: 45940 | C29: 2 | E29: Forelesning/WS
B30: 45943 | C30: 2 | D30: Workshop | E30: Forelesning/WS
B31: 45944 | C31: 4 | D31: Sprint 2. Arbeidet med Brukerautentisering og roller. | E31: Programmering
B32: 45945 | C32: 3 | D32: Sprint 2.
B33: 45946 | C33: 3 | D33: Sprint 2
B34: 45947 | C34: 2 | E34: Forelesning/WS
B35: 45950 | C35: 2 | E35: Forelesning/WS
B36: 45951 | C36: 2 | E36: Forelesning/WS
B37: 45953 | C37: 2 | E37: Møte
B38: 45954 | C38: 2 | E38: Forelesning/WS
B39: 45955 | C39: 5 | D39: Sprint 2. Bruker autentisering og rollesystem | E39: Programmering
B40: 45956 | C40: 4 | D40: Sprint 2. Bruker autentisering og rollesystem | E40: Programmering
...

Sheet Gruppemedlem 2
B1: Timeliste
B2: Navn
B3: Philip André Gaulin | C3: Totalt antall arbeidstimer
C4: =SUBTOTAL(109,Timeliste5711[Antall arbeidstimer]) -> 201.25
B5: Dato(er) | C5: Antall arbeidstimer | D5: Kommentar | E5: Tagg | H5: Oppgave Tag | I5: Antall oppføringer | J5: Timer arbeid med oppgave | K5: %
B6: 45887 | C6: 2 | E6: Forelesning/WS | H6: Programmering | I6: =COUNTIF(E6:E100, "Programmering") -> 5 | J6: =SUMIF(E6:E100, "Programmering", C6:C100) -> 60 | K6: =J6/C4*100 -> 29.813665
B7: 45888 | C7: 2 | E7: Forelesning/WS | H7: Raport | I7: =COUNTIF(E6:E100, "Raport") -> 7 | J7: =SUMIF(E6:E100, "Raport", C6:C100) -> 36.25 | K7: =J7/C4*100 -> 18.012422
B8: 45895 | C8: 2 | E8: Forelesning/WS | H8: Møte | I8: =COUNTIF(E6:E100, "Møte") -> 0 | J8: =SUMIF(E6:E100, "Møte", C6:C100) -> 0 | K8: =J8/C4*100 -> 0
B9: 45901 | C9: 2 | E9: Forelesning/WS | H9: Database | I9: =COUNTIF(E6:E100, "Database") -> 4 | J9: =SUMIF(E6:E100, "Database", C6:C100) -> 29 | K9: =J9/C4*100 -> 14.409938
B10: 45905 | C10: 2 | E10: Forelesning/WS | H10: GitHub | I10: =COUNTIF(E6:E100, "GitHub") -> 8 | J10: =SUMIF(E6:E100, "GitHub", C6:C100) -> 51 | K10: =J10/C4*100 -> 25.341615
B11: 45912 | C11: 2 | E11: Forelesning/WS | H11: Administrativt | I11: =COUNTIF(E6:E100, "Administrativt") -> 0 | J11: =SUMIF(E6:E100, "Administrativt", C6:C100) -> 0 | K11: =J11/C4*100 -> 0
B12: 45901 | C12: 4 | D12: Startet med research for hvordan jeg skulle skrive kravspec hva jeg må tenke på for å faktisk levere et produkt kan brukes | E12: Raport | H12: Forelesning/WS | I12: =COUNTIF(E6:E100, "Forelesning/WS") -> 8 | J12: =SUMIF(E6:E100, "Forelesning/WS", C6:C100) -> 16 | K12: =J12/C4*100 -> 7.9503106
B13: 45902 | C13: 3 | D13: Brukte mye tid på å finne ut av hvilke språk vi skulle bruke til frontend og backaned og hvordan alt dette skulle fungere sammen. | E13: Raport | H13: Veiledning | I13: =COUNTIF(E6:E100, "Veiledning") -> 0 | J13: =SUMIF(E6:E100, "Veiledning", C6:C100) -> 0 | K13: =J13/C4*100 -> 0
B14: 45910 | C14: 6 | D14: startet med å sette opp en liste struktur for kravspecen. og samlet inn informasjon om fremgangsmåter | E14: Raport | H14: Design | I14: =COUNTIF(E6:E100, "Design") -> 0 | J14: =SUMIF(E6:E100, "Design", C6:C100) -> 0 | K14: =J14/C4*100 -> 0
B15: 45911 | C15: 5.25 | D15: fullførte innsaming av informasjon og forståelse av hva som trengtes i appen og satt opp prioritert basert på det. | E15: Raport | H15: Annet | I15: =COUNTIF(E6:E100, "Annet") -> 0 | J15: =SUMIF(E7:E101, "Annet", C6:C100) -> 0 | K15: =J15/C4*100 -> 0
B16: 45919 | C16: 2 | E16: Forelesning/WS
B17: 45920 | C17: 1 | D17: Finne ut av Hvordan jeg skal sette opp strukturen for github repo og finne ut av hvordan regler jeg skal sette opp. | E17: Raport
B18: 45921 | C18: 3 | D18: Dele github med alle som trenger tilgang og skrive litt om metodikken til hvordan github skal fungerer for oss i overleaf. Teste branches med main dev og futures. | E18: GitHub
B19: 45922 | C19: 2 | E19: Forelesning/WS
B20: 45936 | C20: 3 | D20: satt opp sprint 2 og har holdt på med backend på server siden, mer spesifikt database oppsett og automatisert av pulls fra github | E20: GitHub
B21: 45949 | C21: 9 | D21: Feilsøke reverse proxy problemer med java og itstud server. testet flere måter å få apien til å svare på riktig path. Oppdaterte
B22: 45950 | C22: 7 | D22: feilsøke og sette opp shellscripts for automatisering | E22: GitHub
B23: 45951 | C23: 5 | D23: Feilsøke hvorfor frontend og backenden ikke ville kommunisere. (fortsatt nginx) | E23: GitHub
B24: 45953 | C24: 12 | D24: Startet på bilettering system | E24: Programmering
B25: 23-27.10.25 | C25: 15 | D25: Fortsatt arbeid med nginx-konfigurasjon, CORS-problemer og deployment-pipeline | E25: GitHub
B26: 45958 | C26: 8 | D26: Implementert JWT autentisering, Spring Security config og sikker innloggingsflyt | E26: GitHub
B27: 45959 | C27: 12 | D27: Videreutvikling av backend arkitektur, repository-lag og service-lag | E27: Programmering
B28: 45965 | C28: 5 | D28: PostgreSQL-integrasjon, Flyway migrations og database-skjema | E28: Database
B29: 5-6.11.25 | C29: 10 | D29: Brukerregistrering med BCrypt, refaktorering og API-testing | E29: Programmering
B30: 7-8.11.25 | C30: 8 | D30: Databasemodell (ER-diagram), seed-data og SQL-verifisering | E30: Database
B31: 45970 | C31: 14 | D31: Billettkjøp/historikk, gjestebruker, QR-kode generering, admin dashboard | E31: Programmering
B32: 45971 | C32: 6 | D32: Database-skjema refaktorering, unified schema.sql og dokumentasjon | E32: Database
B33: 45972 | C33: 4 | D33: Code review, opprydding, fjernet ubrukte imports og dokumentasjon | E33: GitHub
B34: 12-15.11.25 | C34: 10 | D34: Backend til PostgreSQL kobling, JPA/Hibernate config | E34: Database
B35: 16-18.11.25 | C35: 12 | D35: Repository-klasser, service-lag og REST API-utvidelser | E35: Programmering
B36: 45980 | C36: 6 | D36: Merge main branch, implementering og kjøring av unit tests | E36: GitHub
B37: 45980 | C37: 9 | D37: Skrive rapport | E37: Raport
B38: 45981 | C38: 8 | D38: Ferdigstilling av rapport, testing dokumentasjon og innlevering | E38: Raport
B39: Dato | C39: 0
B40: Dato | C40: 0
...

Sheet Gruppemedlem 3
B1: Timeliste
B2: Navn
B3: Simen Kingsrød | C3: Totalt antall arbeidstimer
C4: =SUBTOTAL(109,Timeliste5712[Antall arbeidstimer]) -> 76.8
B5: Dato(er) | C5: Antall arbeidstimer | D5: Kommentar | E5: Tagg | H5: Oppgave Tag | I5: Antall oppføringer | J5: Timer arbeid med oppgave | K5: %
B6: 45887 | C6: 2 | E6: Forelesning/WS | H6: Programmering | I6: =COUNTIF(E6:E100, "Programmering") -> 1 | J6: =SUMIF(E6:E100, "Programmering", C6:C100) -> 4 | K6: =J6/C4*100 -> 5.2083333
B7: 45888 | C7: 2 | E7: Forelesning/WS | H7: Raport | I7: =COUNTIF(E6:E100, "Raport") -> 6 | J7: =SUMIF(E6:E100, "Raport", C6:C100) -> 8.3 | K7: =J7/C4*100 -> 10.807292
B8: 45891 | C8: 2 | E8: Forelesning/WS | H8: Møte | I8: =COUNTIF(E6:E100, "Møte") -> 2 | J8: =SUMIF(E6:E100, "Møte", C6:C100) -> 4 | K8: =J8/C4*100 -> 5.2083333
B9: 45894 | C9: 2 | E9: Forelesning/WS | H9: Database | I9: =COUNTIF(E6:E100, "Database") -> 0 | J9: =SUMIF(E6:E100, "Database", C6:C100) -> 0 | K9: =J9/C4*100 -> 0
B10: 45895 | C10: 2 | E10: Forelesning/WS | H10: GitHub | I10: =COUNTIF(E6:E100, "GitHub") -> 0 | J10: =SUMIF(E6:E100, "GitHub", C6:C100) -> 0 | K10: =J10/C4*100 -> 0
B11: 45901 | C11: 2 | E11: Forelesning/WS | H11: Administrativt | I11: =COUNTIF(E6:E100, "Administrativt") -> 0 | J11: =SUMIF(E6:E100, "Administrativt", C6:C100) -> 0 | K11: =J11/C4*100 -> 0
B12: 45901 | C12: 1 | E12: Raport | H12: Forelesning/WS | I12: =COUNTIF(E6:E100, "Forelesning/WS") -> 24 | J12: =SUMIF(E6:E100, "Forelesning/WS", C6:C100) -> 48 | K12: =J12/C4*100 -> 62.5
B13: 45903 | C13: 0.5 | E13: Veiledning | H13: Veiledning | I13: =COUNTIF(E6:E100, "Veiledning") -> 2 | J13: =SUMIF(E6:E100, "Veiledning", C6:C100) -> 1.5 | K13: =J13/C4*100 -> 1.953125
B14: 45905 | C14: 2 | E14: Forelesning/WS | H14: Design | I14: =COUNTIF(E6:E100, "Design") -> 2 | J14: =SUMIF(E6:E100, "Design", C6:C100) -> 7 | K14: =J14/C4*100 -> 9.1145833
B15: 45908 | C15: 2 | E15: Forelesning/WS | H15: Annet | I15: =COUNTIF(E6:E100, "Annet") -> 2 | J15: =SUMIF(E7:E101, "Annet", C6:C100) -> 7 | K15: =J15/C4*100 -> 9.1145833
B16: 45912 | C16: 2 | E16: Forelesning/WS
B17: 45912 | C17: 1.3 | E17: Raport
B18: 45915 | C18: 2 | E18: Forelesning/WS
B19: 45919 | C19: 2 | E19: Forelesning/WS
B20: 45922 | C20: 2 | E20: Forelesning/WS
B21: 45929 | C21: 2 | E21: Forelesning/WS
B22: 45936 | C22: 2 | E22: Forelesning/WS
B23: 45936 | C23: 2 | E23: Raport
B24: 45937 | C24: 2 | E24: Forelesning/WS
B25: 45940 | C25: 2 | E25: Forelesning/WS
B26: 45943 | C26: 2 | E26: Forelesning/WS
B27: 45947 | C27: 2 | E27: Forelesning/WS
... B31: 45954 | C31: 2 | E31: Forelesning/WS
B32: 45955 | C32: 4 | D32: Jobbet med ruteplanlegger og testing av API. | E32: Programmering
B33: 45955 | C33: 1 | D33: Research: Satt meg inn i hvordan REST API fungerer i Spring Boot. | E33: Annet
B34: 45955 | C34: 1 | E34: Raport
B35: 45957 | C35: 2 | E35: Forelesning/WS
B36: 45958 | C36: 2 | E36: Forelesning/WS
B37: 45965 | C37: 2 | D37: Gruppemøte | E37: Møte
B38: 45965 | C38: 3 | D38: Designe ny innlogginsside for desktop og mobil. | E38: Design
B39: 45965 | C39: 3 | D39: Plukke opp css igjen og undersøke oppsett av de ulike sidene | E39: Annet
B40: 45966 | C40: 2 | E40: Møte
B41: 45966 | C41: 4 | D41: Design av hjem-side | E41: Design
B42: 45973 | C42: 1 | E42: Veiledning
B43: 45980 | C43: 1 | E43: Raport
...

Sheet Gruppemedlem 4
B1: Timeliste
B2: Navn
B3: Erica Bich Che | C3: Totalt antall arbeidstimer
C4: =SUBTOTAL(109,Timeliste5713[Antall arbeidstimer]) -> 188.5
B5: Dato(er) | C5: Antall arbeidstimer | D5: Kommentar | E5: Tagg | H5: Oppgave Tag | I5: Antall oppføringer | J5: Timer arbeid med oppgave | K5: %
B6: 45887 | C6: 2 | E6: Forelesning/WS | H6: Programmering | I6: =COUNTIF(E6:E110, "Programmering") -> 3 | J6: =SUMIF(E6:E110, "Programmering", C6:C110) -> 18 | K6: =J6/C4*100 -> 9.5490716
B7: 45888 | C7: 2 | E7: Forelesning/WS | H7: Raport | I7: =COUNTIF(E6:E110, "Raport") -> 12 | J7: =SUMIF(E6:E110, "Raport", C6:C110) -> 30 | K7: =J7/C4*100 -> 15.915119
B8: 45891 | C8: 2 | D8: Workshop | E8: Forelesning/WS | H8: Møte | I8: =COUNTIF(E6:E110, "Møte") -> 2 | J8: =SUMIF(E6:E110, "Møte", C6:C110) -> 4 | K8: =J8/C4*100 -> 2.1220159
B9: 45894 | C9: 2 | E9: Forelesning/WS | H9: Database | I9: =COUNTIF(E6:E110, "Database") -> 6 | J9: =SUMIF(E6:E110, "Database", C6:C110) -> 26 | K9: =J9/C4*100 -> 13.793103
B10: 45895 | C10: 2 | D10: Workshop | E10: Forelesning/WS | H10: GitHub | I10: =COUNTIF(E6:E110, "GitHub") -> 3 | J10: =SUMIF(E6:E110, "GitHub", C6:C110) -> 4 | K10: =J10/C4*100 -> 2.1220159
B11: 45901 | C11: 2 | E11: Forelesning/WS | H11: Administrativt | I11: =COUNTIF(E6:E110, "Administrativt") -> 1 | J11: =SUMIF(E6:E110, "Administrativt", C6:C110) -> 4 | K11: =J11/C4*100 -> 2.1220159
B12: 45901 | C12: 2 | E12: Raport | H12: Forelesning/WS | I12: =COUNTIF(E6:E110, "Forelesning/WS") -> 30 | J12: =SUMIF(E6:E110, "Forelesning/WS", C6:C110) -> 60 | K12: =J12/C4*100 -> 31.830239
B13: 45902 | C13: 2 | E13: Forelesning/WS | H13: Veiledning | I13: =COUNTIF(E6:E110, "Veiledning") -> 2 | J13: =SUMIF(E6:E110, "Veiledning", C6:C110) -> 1.5 | K13: =J13/C4*100 -> 0.79575597
B14: 45903 | C14: 0.5 | E14: Veiledning | H14: Design | I14: =COUNTIF(E6:E110, "Design") -> 8 | J14: =SUMIF(E6:E110, "Design", C6:C110) -> 36 | K14: =J14/C4*100 -> 19.098143
B15: 45905 | C15: 2 | D15: Workshop | E15: Forelesning/WS | H15: Annet | I15: =COUNTIF(E6:E110, "Annet") -> 2 | J15: =SUMIF(E7:E111, "Annet", C6:C110) -> 8 | K15: =J15/C4*100 -> 4.2440318
B16: 45908 | C16: 2 | E16: Forelesning/WS
B17: 45909 | C17: 2 | E17: Forelesning/WS
B18: 45912 | C18: 2 | D18: Workshop | E18: Forelesning/WS
B19: 45912 | C19: 1 | E19: Raport
B20: 45915 | C20: 2 | E20: Forelesning/WS
B21: 45885 | C21: 2 | E21: Forelesning/WS
B22: 45919 | C22: 2 | D22: Workshop | E22: Forelesning/WS
B23: 45922 | C23: 2 | D23: Workshop | E23: Forelesning/WS
B24: 45923 | C24: 2 | E24: Forelesning/WS
B25: 45926 | C25: 2 | E25: Forelesning/WS
B26: 45926 | C26: 2 | D26: Endret på rapporten etter tilbakemelding fra oblig 2 | E26: Raport
B27: 45926 | C27: 4 | D27: Installert postgreSQL og gjort research | E27: Database
B28: 45929 | C28: 2 | E28: Forelesning/WS
B29: 45929 | C29: 3 | D29: Rapport til Oblig 4 | E29: Raport
B30: 45929 | C30: 2 | D30: ER-diagram til database | E30: Database
B31: 45930 | C31: 2 | E31: Forelesning/WS
B32: 45930 | C32: 8 | D32: Opprettelse av database | E32: Database
B33: 45933 | C33: 2 | E33: Forelesning/WS
B34: 45935 | C34: 1 | E34: GitHub
B35: 45936 | C35: 2 | D35: Workshop | E35: Forelesning/WS
B36: 45936 | C36: 2 | E36: Raport
B37: 45937 | C37: 1 | E37: Raport
B38: 45937 | C38: 2 | E38: Forelesning/WS
B39: 45940 | C39: 2 | E39: Forelesning/WS
B40: 45943 | C40: 2 | D40: Workshop | E40: Forelesning/WS
...

Sheet Gruppemedlem 5
B1: Timeliste
B2: Navn
B3: Mohamed Abdullahi Mahamed | C3: Totalt antall arbeidstimer
C4: =SUBTOTAL(109,Timeliste5714[Antall arbeidstimer]) -> 69
B5: Dato(er) | C5: Antall arbeidstimer | D5: Kommentar | E5: Tagg | H5: Oppgave Tag | I5: Antall oppføringer | J5: Timer arbeid med oppgave | K5: %
B6: 45905 | C6: 2 | D6: Workshop | E6: Forelesning/WS | H6: Programmering | I6: =COUNTIF(E6:E100, "Programmering") -> 6 | J6: =SUMIF(E6:E100, "Programmering", C6:C100) -> 29 | K6: =J6/C4*100 -> 42.028986
B7: 45908 | C7: 2 | D7: Workshop | E7: Forelesning/WS | H7: Raport | I7: =COUNTIF(E6:E100, "Raport") -> 3 | J7: =SUMIF(E6:E100, "Raport", C6:C100) -> 6 | K7: =J7/C4*100 -> 8.6956522
B8: 45909 | C8: 2 | D8: WorkShop | E8: Forelesning/WS | H8: Møte | I8: =COUNTIF(E6:E100, "Møte") -> 0 | J8: =SUMIF(E6:E100, "Møte", C6:C100) -> 0 | K8: =J8/C4*100 -> 0
B9: 45908 | C9: 2 | D9: Forelesning | E9: Forelesning/WS | H9: Database | I9: =COUNTIF(E6:E100, "Database") -> 0 | J9: =SUMIF(E6:E100, "Database", C6:C100) -> 0 | K9: =J9/C4*100 -> 0
B10: 45909 | C10: 2 | D10: Forelesning | E10: Forelesning/WS | H10: GitHub | I10: =COUNTIF(E6:E100, "GitHub") -> 3 | J10: =SUMIF(E6:E100, "GitHub", C6:C100) -> 10 | K10: =J10/C4*100 -> 14.492754
B11: 45919 | C11: 2 | D11: Workshop | E11: Forelesning/WS | H11: Administrativt | I11: =COUNTIF(E6:E100, "Administrativt") -> 0 | J11: =SUMIF(E6:E100, "Administrativt", C6:C100) -> 0 | K11: =J11/C4*100 -> 0
B12: 45922 | C12: 2 | D12: Workshop | E12: Forelesning/WS | H12: Forelesning/WS | I12: =COUNTIF(E6:E100, "Forelesning/WS") -> 8 | J12: =SUMIF(E6:E100, "Forelesning/WS", C6:C100) -> 16 | K12: =J12/C4*100 -> 23.188406
B13: 45925 | C13: 3 | D13: research av piplines | E13: Annet | H13: Veiledning | I13: =COUNTIF(E6:E100, "Veiledning") -> 1 | J13: =SUMIF(E6:E100, "Veiledning", C6:C100) -> 3 | K13: =J13/C4*100 -> 4.3478261
B14: 45929 | C14: 2 | D14: research av gitub | E14: GitHub | H14: Design | I14: =COUNTIF(E6:E100, "Design") -> 0 | J14: =SUMIF(E6:E100, "Design", C6:C100) -> 0 | K14: =J14/C4*100 -> 0
B15: 45933 | C15: 2 | D15: research av pipelines | E15: Annet | H15: Annet | I15: =COUNTIF(E6:E100, "Annet") -> 2 | J15: =SUMIF(E7:E101, "Annet", C6:C100) -> 4 | K15: =J15/C4*100 -> 5.7971014
B16: 45935 | C16: 3 | D16: reseach av github | E16: GitHub
B17: 45943 | C17: 2 | D17: Workshop | E17: Forelesning/WS
B18: 45945 | C18: 3 | D18: fikk veiledning av en person fra en annen gruppe om hvilken metode som er best for å få fram sanntid | E18: Veiledning
B19: 45946 | C19: 6 | D19: videre research på hvordan man bruker en-tur api og litt testing | E19: Programmering
B20: 45950 | C20: 5 | D20: programmering av sanntidsdata | E20: Programmering
B21: 45953 | C21: 6 | D21: videre programmering sv sanntids data og begynt på søkefunksjon | E21: Programmering
B22: 45955 | C22: 5 | D22: ferdig gjørelse av søkefunksjon og enkel html side | E22: Programmering
B23: 45956 | C23: 5 | D23: finjustering og pushin | E23: GitHub
B24: 45956 | C24: 2 | D24: rapport oblig 5 | E24: Raport
B25: 45964 | C25: 5 | D25: jobbe med sanntids | E25: Programmering
B26: 45970 | C26: 2 | D26: forbedringer/optimaliseringer | E26: Programmering
B27: 45977 | C27: 2 | D27: rapport | E27: Raport
B28: 45982 | C28: 2 | D28: finjustering av rapport | E28: Raport
B29: Dato
B30: Dato | C30: 0
B31: Dato | C31: 0
B32: Dato | C32: 0
B33: Dato | C33: 0
B34: Dato | C34: 0
B35: Dato | C35: 0
B36: Dato | C36: 0
B37: Dato | C37: 0
B38: Dato | C38: 0
B39: Dato | C39: 0
B40: Dato | C40: 0
...

Sheet Total
A1: Navn | B1: Timer
A2: =KolonnetittelOmråde1..E6.1 -> Jimmy Bui | B2: ='Gruppemedlem 1'!C4 -> 116.6
A3: ='Gruppemedlem 2'!B3 -> Philip André Gaulin | B3: ='Gruppemedlem 2'!C4 -> 201.25
A4: ='Gruppemedlem 3'!B3 -> Simen Kingsrød | B4: ='Gruppemedlem 3'!C4 -> 76.8
A5: ='Gruppemedlem 4'!B3 -> Erica Bich Che | B5: ='Gruppemedlem 4'!C4 -> 188.5
A6: ='Gruppemedlem 5'!B3 -> Mohamed Abdullahi Mahamed | B6: ='Gruppemedlem 5'!C4 -> 69
A7: Total | B7: =SUM(B2:B6) -> 652.15

Sheet DroppdownTable
B2: Programmering
B3: Raport
B4: Møte
B5: Database
B6: GitHub
B7: Administrativt
B8: Forelesning/WS
B9: Veiledning
B10: Design
B11: Annet
